============================= test session starts ==============================
platform linux -- Python 3.11.10, pytest-8.3.4, pluggy-1.5.0 -- /home/runner/workspace/.pythonlibs/bin/python
cachedir: .pytest_cache
rootdir: /home/runner/workspace
configfile: pyproject.toml
plugins: anyio-4.7.0, asyncio-0.25.2, cov-6.0.0
asyncio: mode=Mode.STRICT, asyncio_default_fixture_loop_scope=None
collecting ... collected 7 items / 1 error / 6 deselected / 1 selected
run-last-failure: rerun previous 1 failure (skipped 7 files)

==================================== ERRORS ====================================
__________________ ERROR collecting tests/test_interfaces.py ___________________
.pythonlibs/lib/python3.11/site-packages/_pytest/python.py:493: in importtestmodule
    mod = import_path(
.pythonlibs/lib/python3.11/site-packages/_pytest/pathlib.py:587: in import_path
    importlib.import_module(module_name)
/nix/store/clx0mcir7qw8zk36zbr4jra789g3knf6-python3-3.11.10/lib/python3.11/importlib/__init__.py:126: in import_module
    return _bootstrap._gcd_import(name[level:], package, level)
<frozen importlib._bootstrap>:1204: in _gcd_import
    ???
<frozen importlib._bootstrap>:1176: in _find_and_load
    ???
<frozen importlib._bootstrap>:1147: in _find_and_load_unlocked
    ???
<frozen importlib._bootstrap>:690: in _load_unlocked
    ???
.pythonlibs/lib/python3.11/site-packages/_pytest/assertion/rewrite.py:175: in exec_module
    source_stat, co = _rewrite_test(fn, self.config)
.pythonlibs/lib/python3.11/site-packages/_pytest/assertion/rewrite.py:355: in _rewrite_test
    tree = ast.parse(source, filename=strfn)
/nix/store/clx0mcir7qw8zk36zbr4jra789g3knf6-python3-3.11.10/lib/python3.11/ast.py:50: in parse
    return compile(source, filename, mode, flags,
E     File "/home/runner/workspace/tests/test_interfaces.py", line 65
E       assert project_manager is None or isinstance(project_manager, str)
E   IndentationError: unexpected indent
=============================== warnings summary ===============================
.pythonlibs/lib/python3.11/site-packages/pydantic/_internal/_config.py:345
  /home/runner/workspace/.pythonlibs/lib/python3.11/site-packages/pydantic/_internal/_config.py:345: UserWarning: Valid config keys have changed in V2:
  * 'orm_mode' has been renamed to 'from_attributes'
    warnings.warn(message, UserWarning)

-- Docs: https://docs.pytest.org/en/stable/how-to/capture-warnings.html
=========================== short test summary info ============================
ERROR tests/test_interfaces.py
!!!!!!!!!!!!!!!!!!!! Interrupted: 1 error during collection !!!!!!!!!!!!!!!!!!!!
================== 6 deselected, 1 warning, 1 error in 0.34s ===================
