============================= test session starts ==============================
platform linux -- Python 3.11.10, pytest-8.3.4, pluggy-1.5.0 -- /home/runner/workspace/.pythonlibs/bin/python
cachedir: .pytest_cache
rootdir: /home/runner/workspace
configfile: pyproject.toml
plugins: anyio-4.7.0, asyncio-0.25.2, cov-6.0.0
asyncio: mode=Mode.STRICT, asyncio_default_fixture_loop_scope=None
collecting ... collected 25 items / 24 deselected / 1 selected
run-last-failure: rerun previous 1 failure (skipped 9 files)

tests/test_xls_analyzer.py::test_xls_analyzer_dash_to_none_conversion FAILED [100%]

=================================== FAILURES ===================================
__________________ test_xls_analyzer_dash_to_none_conversion ___________________

tmp_path = PosixPath('/tmp/pytest-of-runner/pytest-18/test_xls_analyzer_dash_to_none0')

    def test_xls_analyzer_dash_to_none_conversion(tmp_path):
        """Test that dash values are converted to None during Excel parsing"""
        data = {
            'Category': ['Development'],
            'Customer': ['-'],
            'Project': ['-'],
            'Hours': [8.0],
            'Date': ['2024-10-07']
        }
        excel_file = create_test_excel(tmp_path, data)
    
        with open(excel_file, "rb") as f:
            contents = f.read()
            analyzer = XLSAnalyzer()
            records = analyzer.read_excel(contents)
    
            assert len(records) == 1
>           assert records[0]['Customer'] is None
E           AssertionError: assert '-' is None

tests/test_xls_analyzer.py:22: AssertionError
----------------------------- Captured stdout call -----------------------------
{"timestamp": "2025-02-11T20:13:13.253009", "level": "INFO", "correlation_id": "undefined", "logger": "TimesheetTracker", "message": "Successfully parsed 1 records from Excel file", "context": {}}
------------------------------ Captured log call -------------------------------
INFO     TimesheetTracker:logger.py:32 {"message": "Successfully parsed 1 records from Excel file", "timestamp": "2025-02-11T20:13:13.253148", "context": {}}
=============================== warnings summary ===============================
.pythonlibs/lib/python3.11/site-packages/pydantic/_internal/_config.py:345
  /home/runner/workspace/.pythonlibs/lib/python3.11/site-packages/pydantic/_internal/_config.py:345: UserWarning: Valid config keys have changed in V2:
  * 'orm_mode' has been renamed to 'from_attributes'
    warnings.warn(message, UserWarning)

-- Docs: https://docs.pytest.org/en/stable/how-to/capture-warnings.html
=========================== short test summary info ============================
FAILED tests/test_xls_analyzer.py::test_xls_analyzer_dash_to_none_conversion
================= 1 failed, 24 deselected, 1 warning in 0.19s ==================
