INFO:     Application startup complete.
{"timestamp": "2025-02-12T02:20:09.454651", "level": "INFO", "correlation_id": "89aed6b3-038a-44d5-9e2d-4adaebd1a80c", "logger": "TimesheetTracker", "message": "Incoming request", "context": {"correlation_id": "89aed6b3-038a-44d5-9e2d-4adaebd1a80c", "method": "GET", "url": "http://6ed7ce35-85b3-498b-9e9b-4d63631ed8e3-00-2owzgyvztotfg.worf.replit.dev/docs", "client_host": "172.31.128.43", "headers": {"host": "6ed7ce35-85b3-498b-9e9b-4d63631ed8e3-00-2owzgyvztotfg.worf.replit.dev", "user-agent": "Mozilla/5.0 (Windows NT 10.0; Win64; x64) AppleWebKit/537.36 (KHTML, like Gecko) Chrome/132.0.0.0 Safari/537.36 Edg/132.0.0.0", "accept": "text/html,application/xhtml+xml,application/xml;q=0.9,image/avif,image/webp,image/apng,*/*;q=0.8,application/signed-exchange;v=b3;q=0.7", "accept-encoding": "identity, gzip, deflate, br, zstd", "accept-language": "en-US,en;q=0.9", "referer": "https://6ed7ce35-85b3-498b-9e9b-4d63631ed8e3-00-2owzgyvztotfg.worf.replit.dev/__replco/workspace_iframe.html?initialPath=%2Fdocs%23%2Fdefault%2Finitialize_database_init_db__post&id=%3Ar4f6%3A", "sec-ch-ua": "\"Not A(Brand\";v=\"8\", \"Chromium\";v=\"132\", \"Microsoft Edge\";v=\"132\"", "sec-ch-ua-mobile": "?0", "sec-ch-ua-platform": "\"Windows\"", "sec-fetch-dest": "iframe", "sec-fetch-mode": "navigate", "sec-fetch-site": "same-origin", "upgrade-insecure-requests": "1", "x-forwarded-for": "67.11.111.13, 165.225.36.171, 10.83.2.23", "x-forwarded-proto": "https", "x-replit-user-bio": "", "x-replit-user-id": "", "x-replit-user-name": "", "x-replit-user-profile-image": "", "x-replit-user-roles": "", "x-replit-user-teams": "", "x-replit-user-url": ""}, "path_params": {}, "query_params": {}, "request_id": null, "path": "/docs"}}
{"timestamp": "2025-02-12T02:20:09.455664", "level": "INFO", "correlation_id": "89aed6b3-038a-44d5-9e2d-4adaebd1a80c", "logger": "TimesheetTracker", "message": "Request completed successfully", "context": {"correlation_id": "89aed6b3-038a-44d5-9e2d-4adaebd1a80c", "status_code": 200, "process_time_ms": "2.78", "response_headers": {"content-length": "931", "content-type": "text/html; charset=utf-8"}, "content_type": "text/html; charset=utf-8", "method": "GET", "path": "/docs"}}
{"timestamp": "2025-02-12T02:20:09.456409", "level": "DEBUG", "correlation_id": "89aed6b3-038a-44d5-9e2d-4adaebd1a80c", "logger": "TimesheetTracker", "message": {"message": "Adding CORS headers to response", "timestamp": "2025-02-12T02:20:09.456246", "context": {"correlation_id": null, "method": "GET", "path": "/docs", "status_code": 200}}, "context": {}}
INFO:     172.31.128.43:32796 - "GET /docs HTTP/1.1" 200 OK
{"timestamp": "2025-02-12T02:20:10.999836", "level": "INFO", "correlation_id": "89aed6b3-038a-44d5-9e2d-4adaebd1a80c", "logger": "TimesheetTracker", "message": "Incoming request", "context": {"correlation_id": "89aed6b3-038a-44d5-9e2d-4adaebd1a80c", "method": "GET", "url": "http://6ed7ce35-85b3-498b-9e9b-4d63631ed8e3-00-2owzgyvztotfg.worf.replit.dev/openapi.json", "client_host": "172.31.128.43", "headers": {"host": "6ed7ce35-85b3-498b-9e9b-4d63631ed8e3-00-2owzgyvztotfg.worf.replit.dev", "user-agent": "Mozilla/5.0 (Windows NT 10.0; Win64; x64) AppleWebKit/537.36 (KHTML, like Gecko) Chrome/132.0.0.0 Safari/537.36 Edg/132.0.0.0", "accept": "application/json,*/*", "accept-encoding": "gzip, deflate, br, zstd", "accept-language": "en-US,en;q=0.9", "referer": "https://6ed7ce35-85b3-498b-9e9b-4d63631ed8e3-00-2owzgyvztotfg.worf.replit.dev/docs", "sec-ch-ua": "\"Not A(Brand\";v=\"8\", \"Chromium\";v=\"132\", \"Microsoft Edge\";v=\"132\"", "sec-ch-ua-mobile": "?0", "sec-ch-ua-platform": "\"Windows\"", "sec-fetch-dest": "empty", "sec-fetch-mode": "cors", "sec-fetch-site": "same-origin", "x-forwarded-for": "67.11.111.13, 165.225.36.171, 10.83.2.23", "x-forwarded-proto": "https", "x-replit-user-bio": "", "x-replit-user-id": "", "x-replit-user-name": "", "x-replit-user-profile-image": "", "x-replit-user-roles": "", "x-replit-user-teams": "", "x-replit-user-url": ""}, "path_params": {}, "query_params": {}, "request_id": null, "path": "/openapi.json"}}
{"timestamp": "2025-02-12T02:20:11.045008", "level": "INFO", "correlation_id": "89aed6b3-038a-44d5-9e2d-4adaebd1a80c", "logger": "TimesheetTracker", "message": "Request completed successfully", "context": {"correlation_id": "89aed6b3-038a-44d5-9e2d-4adaebd1a80c", "status_code": 200, "process_time_ms": "45.39", "response_headers": {"content-length": "22961", "content-type": "application/json"}, "content_type": "application/json", "method": "GET", "path": "/openapi.json"}}
{"timestamp": "2025-02-12T02:20:11.046093", "level": "DEBUG", "correlation_id": "89aed6b3-038a-44d5-9e2d-4adaebd1a80c", "logger": "TimesheetTracker", "message": {"message": "Adding CORS headers to response", "timestamp": "2025-02-12T02:20:11.045826", "context": {"correlation_id": "89aed6b3-038a-44d5-9e2d-4adaebd1a80c", "method": "GET", "path": "/openapi.json", "status_code": 200}}, "context": {}}
INFO:     172.31.128.43:32796 - "GET /openapi.json HTTP/1.1" 200 OK
WARNING:  WatchFiles detected changes in 'database/database.py'. Reloading...
INFO:     Shutting down
INFO:     Waiting for application shutdown.
INFO:     Application shutdown complete.
INFO:     Finished server process [3236]
{"timestamp": "2025-02-12T02:23:59.439467", "level": "INFO", "correlation_id": "undefined", "logger": "TimesheetTracker", "message": "Creating database engine with connection settings", "context": {}}
{"timestamp": "2025-02-12T02:23:59.440570", "level": "DEBUG", "correlation_id": "undefined", "logger": "TimesheetTracker", "message": "Connection parameters: pool_size=5, max_overflow=10, pool_timeout=30", "context": {}}
{"timestamp": "2025-02-12T02:23:59.704604", "level": "ERROR", "correlation_id": "undefined", "logger": "TimesheetTracker", "message": "Failed to create database engine: (psycopg2.OperationalError) connection to server at \"ep-damp-art-a8ixdln.eastus2.azure.neon.tech\" (52.167.188.143), port 5432 failed: ERROR:  password authentication failed for user 'neondb_owner'\n\n(Background on this error at: https://sqlalche.me/e/20/e3q8)", "context": {}}
{"timestamp": "2025-02-12T02:23:59.713573", "level": "ERROR", "correlation_id": "undefined", "logger": "TimesheetTracker", "message": "Database initialization error details:", "context": {}, "exception": "Traceback (most recent call last):\n  File \"/home/runner/workspace/.pythonlibs/lib/python3.11/site-packages/sqlalchemy/engine/base.py\", line 146, in __init__\n    self._dbapi_connection = engine.raw_connection()\n                             ^^^^^^^^^^^^^^^^^^^^^^^\n  File \"/home/runner/workspace/.pythonlibs/lib/python3.11/site-packages/sqlalchemy/engine/base.py\", line 3302, in raw_connection\n    return self.pool.connect()\n           ^^^^^^^^^^^^^^^^^^^\n  File \"/home/runner/workspace/.pythonlibs/lib/python3.11/site-packages/sqlalchemy/pool/base.py\", line 449, in connect\n    return _ConnectionFairy._checkout(self)\n           ^^^^^^^^^^^^^^^^^^^^^^^^^^^^^^^^\n  File \"/home/runner/workspace/.pythonlibs/lib/python3.11/site-packages/sqlalchemy/pool/base.py\", line 1263, in _checkout\n    fairy = _ConnectionRecord.checkout(pool)\n            ^^^^^^^^^^^^^^^^^^^^^^^^^^^^^^^^\n  File \"/home/runner/workspace/.pythonlibs/lib/python3.11/site-packages/sqlalchemy/pool/base.py\", line 712, in checkout\n    rec = pool._do_get()\n          ^^^^^^^^^^^^^^\n  File \"/home/runner/workspace/.pythonlibs/lib/python3.11/site-packages/sqlalchemy/pool/impl.py\", line 179, in _do_get\n    with util.safe_reraise():\n  File \"/home/runner/workspace/.pythonlibs/lib/python3.11/site-packages/sqlalchemy/util/langhelpers.py\", line 146, in __exit__\n    raise exc_value.with_traceback(exc_tb)\n  File \"/home/runner/workspace/.pythonlibs/lib/python3.11/site-packages/sqlalchemy/pool/impl.py\", line 177, in _do_get\n    return self._create_connection()\n           ^^^^^^^^^^^^^^^^^^^^^^^^^\n  File \"/home/runner/workspace/.pythonlibs/lib/python3.11/site-packages/sqlalchemy/pool/base.py\", line 390, in _create_connection\n    return _ConnectionRecord(self)\n           ^^^^^^^^^^^^^^^^^^^^^^^\n  File \"/home/runner/workspace/.pythonlibs/lib/python3.11/site-packages/sqlalchemy/pool/base.py\", line 674, in __init__\n    self.__connect()\n  File \"/home/runner/workspace/.pythonlibs/lib/python3.11/site-packages/sqlalchemy/pool/base.py\", line 900, in __connect\n    with util.safe_reraise():\n  File \"/home/runner/workspace/.pythonlibs/lib/python3.11/site-packages/sqlalchemy/util/langhelpers.py\", line 146, in __exit__\n    raise exc_value.with_traceback(exc_tb)\n  File \"/home/runner/workspace/.pythonlibs/lib/python3.11/site-packages/sqlalchemy/pool/base.py\", line 896, in __connect\n    self.dbapi_connection = connection = pool._invoke_creator(self)\n                                         ^^^^^^^^^^^^^^^^^^^^^^^^^^\n  File \"/home/runner/workspace/.pythonlibs/lib/python3.11/site-packages/sqlalchemy/engine/create.py\", line 643, in connect\n    return dialect.connect(*cargs, **cparams)\n           ^^^^^^^^^^^^^^^^^^^^^^^^^^^^^^^^^^\n  File \"/home/runner/workspace/.pythonlibs/lib/python3.11/site-packages/sqlalchemy/engine/default.py\", line 621, in connect\n    return self.loaded_dbapi.connect(*cargs, **cparams)\n           ^^^^^^^^^^^^^^^^^^^^^^^^^^^^^^^^^^^^^^^^^^^^\n  File \"/home/runner/workspace/.pythonlibs/lib/python3.11/site-packages/psycopg2/__init__.py\", line 122, in connect\n    conn = _connect(dsn, connection_factory=connection_factory, **kwasync)\n           ^^^^^^^^^^^^^^^^^^^^^^^^^^^^^^^^^^^^^^^^^^^^^^^^^^^^^^^^^^^^^^^\npsycopg2.OperationalError: connection to server at \"ep-damp-art-a8ixdln.eastus2.azure.neon.tech\" (52.167.188.143), port 5432 failed: ERROR:  password authentication failed for user 'neondb_owner'\n\n\nThe above exception was the direct cause of the following exception:\n\nTraceback (most recent call last):\n  File \"/home/runner/workspace/database/database.py\", line 31, in <module>\n    with engine.connect() as conn:\n         ^^^^^^^^^^^^^^^^\n  File \"/home/runner/workspace/.pythonlibs/lib/python3.11/site-packages/sqlalchemy/engine/base.py\", line 3278, in connect\n    return self._connection_cls(self)\n           ^^^^^^^^^^^^^^^^^^^^^^^^^^\n  File \"/home/runner/workspace/.pythonlibs/lib/python3.11/site-packages/sqlalchemy/engine/base.py\", line 148, in __init__\n    Connection._handle_dbapi_exception_noconnection(\n  File \"/home/runner/workspace/.pythonlibs/lib/python3.11/site-packages/sqlalchemy/engine/base.py\", line 2442, in _handle_dbapi_exception_noconnection\n    raise sqlalchemy_exception.with_traceback(exc_info[2]) from e\n  File \"/home/runner/workspace/.pythonlibs/lib/python3.11/site-packages/sqlalchemy/engine/base.py\", line 146, in __init__\n    self._dbapi_connection = engine.raw_connection()\n                             ^^^^^^^^^^^^^^^^^^^^^^^\n  File \"/home/runner/workspace/.pythonlibs/lib/python3.11/site-packages/sqlalchemy/engine/base.py\", line 3302, in raw_connection\n    return self.pool.connect()\n           ^^^^^^^^^^^^^^^^^^^\n  File \"/home/runner/workspace/.pythonlibs/lib/python3.11/site-packages/sqlalchemy/pool/base.py\", line 449, in connect\n    return _ConnectionFairy._checkout(self)\n           ^^^^^^^^^^^^^^^^^^^^^^^^^^^^^^^^\n  File \"/home/runner/workspace/.pythonlibs/lib/python3.11/site-packages/sqlalchemy/pool/base.py\", line 1263, in _checkout\n    fairy = _ConnectionRecord.checkout(pool)\n            ^^^^^^^^^^^^^^^^^^^^^^^^^^^^^^^^\n  File \"/home/runner/workspace/.pythonlibs/lib/python3.11/site-packages/sqlalchemy/pool/base.py\", line 712, in checkout\n    rec = pool._do_get()\n          ^^^^^^^^^^^^^^\n  File \"/home/runner/workspace/.pythonlibs/lib/python3.11/site-packages/sqlalchemy/pool/impl.py\", line 179, in _do_get\n    with util.safe_reraise():\n  File \"/home/runner/workspace/.pythonlibs/lib/python3.11/site-packages/sqlalchemy/util/langhelpers.py\", line 146, in __exit__\n    raise exc_value.with_traceback(exc_tb)\n  File \"/home/runner/workspace/.pythonlibs/lib/python3.11/site-packages/sqlalchemy/pool/impl.py\", line 177, in _do_get\n    return self._create_connection()\n           ^^^^^^^^^^^^^^^^^^^^^^^^^\n  File \"/home/runner/workspace/.pythonlibs/lib/python3.11/site-packages/sqlalchemy/pool/base.py\", line 390, in _create_connection\n    return _ConnectionRecord(self)\n           ^^^^^^^^^^^^^^^^^^^^^^^\n  File \"/home/runner/workspace/.pythonlibs/lib/python3.11/site-packages/sqlalchemy/pool/base.py\", line 674, in __init__\n    self.__connect()\n  File \"/home/runner/workspace/.pythonlibs/lib/python3.11/site-packages/sqlalchemy/pool/base.py\", line 900, in __connect\n    with util.safe_reraise():\n  File \"/home/runner/workspace/.pythonlibs/lib/python3.11/site-packages/sqlalchemy/util/langhelpers.py\", line 146, in __exit__\n    raise exc_value.with_traceback(exc_tb)\n  File \"/home/runner/workspace/.pythonlibs/lib/python3.11/site-packages/sqlalchemy/pool/base.py\", line 896, in __connect\n    self.dbapi_connection = connection = pool._invoke_creator(self)\n                                         ^^^^^^^^^^^^^^^^^^^^^^^^^^\n  File \"/home/runner/workspace/.pythonlibs/lib/python3.11/site-packages/sqlalchemy/engine/create.py\", line 643, in connect\n    return dialect.connect(*cargs, **cparams)\n           ^^^^^^^^^^^^^^^^^^^^^^^^^^^^^^^^^^\n  File \"/home/runner/workspace/.pythonlibs/lib/python3.11/site-packages/sqlalchemy/engine/default.py\", line 621, in connect\n    return self.loaded_dbapi.connect(*cargs, **cparams)\n           ^^^^^^^^^^^^^^^^^^^^^^^^^^^^^^^^^^^^^^^^^^^^\n  File \"/home/runner/workspace/.pythonlibs/lib/python3.11/site-packages/psycopg2/__init__.py\", line 122, in connect\n    conn = _connect(dsn, connection_factory=connection_factory, **kwasync)\n           ^^^^^^^^^^^^^^^^^^^^^^^^^^^^^^^^^^^^^^^^^^^^^^^^^^^^^^^^^^^^^^^\nsqlalchemy.exc.OperationalError: (psycopg2.OperationalError) connection to server at \"ep-damp-art-a8ixdln.eastus2.azure.neon.tech\" (52.167.188.143), port 5432 failed: ERROR:  password authentication failed for user 'neondb_owner'\n\n(Background on this error at: https://sqlalche.me/e/20/e3q8)"}
Process SpawnProcess-6:
Traceback (most recent call last):
  File "/home/runner/workspace/.pythonlibs/lib/python3.11/site-packages/sqlalchemy/engine/base.py", line 146, in __init__
    self._dbapi_connection = engine.raw_connection()
                             ^^^^^^^^^^^^^^^^^^^^^^^
  File "/home/runner/workspace/.pythonlibs/lib/python3.11/site-packages/sqlalchemy/engine/base.py", line 3302, in raw_connection
    return self.pool.connect()
           ^^^^^^^^^^^^^^^^^^^
  File "/home/runner/workspace/.pythonlibs/lib/python3.11/site-packages/sqlalchemy/pool/base.py", line 449, in connect
    return _ConnectionFairy._checkout(self)
           ^^^^^^^^^^^^^^^^^^^^^^^^^^^^^^^^
  File "/home/runner/workspace/.pythonlibs/lib/python3.11/site-packages/sqlalchemy/pool/base.py", line 1263, in _checkout
    fairy = _ConnectionRecord.checkout(pool)
            ^^^^^^^^^^^^^^^^^^^^^^^^^^^^^^^^
  File "/home/runner/workspace/.pythonlibs/lib/python3.11/site-packages/sqlalchemy/pool/base.py", line 712, in checkout
    rec = pool._do_get()
          ^^^^^^^^^^^^^^
  File "/home/runner/workspace/.pythonlibs/lib/python3.11/site-packages/sqlalchemy/pool/impl.py", line 179, in _do_get
    with util.safe_reraise():
  File "/home/runner/workspace/.pythonlibs/lib/python3.11/site-packages/sqlalchemy/util/langhelpers.py", line 146, in __exit__
    raise exc_value.with_traceback(exc_tb)
  File "/home/runner/workspace/.pythonlibs/lib/python3.11/site-packages/sqlalchemy/pool/impl.py", line 177, in _do_get
    return self._create_connection()
           ^^^^^^^^^^^^^^^^^^^^^^^^^
  File "/home/runner/workspace/.pythonlibs/lib/python3.11/site-packages/sqlalchemy/pool/base.py", line 390, in _create_connection
    return _ConnectionRecord(self)
           ^^^^^^^^^^^^^^^^^^^^^^^
  File "/home/runner/workspace/.pythonlibs/lib/python3.11/site-packages/sqlalchemy/pool/base.py", line 674, in __init__
    self.__connect()
  File "/home/runner/workspace/.pythonlibs/lib/python3.11/site-packages/sqlalchemy/pool/base.py", line 900, in __connect
    with util.safe_reraise():
  File "/home/runner/workspace/.pythonlibs/lib/python3.11/site-packages/sqlalchemy/util/langhelpers.py", line 146, in __exit__
    raise exc_value.with_traceback(exc_tb)
  File "/home/runner/workspace/.pythonlibs/lib/python3.11/site-packages/sqlalchemy/pool/base.py", line 896, in __connect
    self.dbapi_connection = connection = pool._invoke_creator(self)
                                         ^^^^^^^^^^^^^^^^^^^^^^^^^^
  File "/home/runner/workspace/.pythonlibs/lib/python3.11/site-packages/sqlalchemy/engine/create.py", line 643, in connect
    return dialect.connect(*cargs, **cparams)
           ^^^^^^^^^^^^^^^^^^^^^^^^^^^^^^^^^^
  File "/home/runner/workspace/.pythonlibs/lib/python3.11/site-packages/sqlalchemy/engine/default.py", line 621, in connect
    return self.loaded_dbapi.connect(*cargs, **cparams)
           ^^^^^^^^^^^^^^^^^^^^^^^^^^^^^^^^^^^^^^^^^^^^
  File "/home/runner/workspace/.pythonlibs/lib/python3.11/site-packages/psycopg2/__init__.py", line 122, in connect
    conn = _connect(dsn, connection_factory=connection_factory, **kwasync)
           ^^^^^^^^^^^^^^^^^^^^^^^^^^^^^^^^^^^^^^^^^^^^^^^^^^^^^^^^^^^^^^^
psycopg2.OperationalError: connection to server at "ep-damp-art-a8ixdln.eastus2.azure.neon.tech" (52.167.188.143), port 5432 failed: ERROR:  password authentication failed for user 'neondb_owner'


The above exception was the direct cause of the following exception:

Traceback (most recent call last):
  File "/nix/store/clx0mcir7qw8zk36zbr4jra789g3knf6-python3-3.11.10/lib/python3.11/multiprocessing/process.py", line 314, in _bootstrap
    self.run()
  File "/nix/store/clx0mcir7qw8zk36zbr4jra789g3knf6-python3-3.11.10/lib/python3.11/multiprocessing/process.py", line 108, in run
    self._target(*self._args, **self._kwargs)
  File "/home/runner/workspace/.pythonlibs/lib/python3.11/site-packages/uvicorn/_subprocess.py", line 80, in subprocess_started
    target(sockets=sockets)
  File "/home/runner/workspace/.pythonlibs/lib/python3.11/site-packages/uvicorn/server.py", line 66, in run
    return asyncio.run(self.serve(sockets=sockets))
           ^^^^^^^^^^^^^^^^^^^^^^^^^^^^^^^^^^^^^^^^
  File "/nix/store/clx0mcir7qw8zk36zbr4jra789g3knf6-python3-3.11.10/lib/python3.11/asyncio/runners.py", line 190, in run
    return runner.run(main)
           ^^^^^^^^^^^^^^^^
  File "/nix/store/clx0mcir7qw8zk36zbr4jra789g3knf6-python3-3.11.10/lib/python3.11/asyncio/runners.py", line 118, in run
    return self._loop.run_until_complete(task)
           ^^^^^^^^^^^^^^^^^^^^^^^^^^^^^^^^^^^
  File "uvloop/loop.pyx", line 1518, in uvloop.loop.Loop.run_until_complete
  File "/home/runner/workspace/.pythonlibs/lib/python3.11/site-packages/uvicorn/server.py", line 70, in serve
    await self._serve(sockets)
  File "/home/runner/workspace/.pythonlibs/lib/python3.11/site-packages/uvicorn/server.py", line 77, in _serve
    config.load()
  File "/home/runner/workspace/.pythonlibs/lib/python3.11/site-packages/uvicorn/config.py", line 435, in load
    self.loaded_app = import_from_string(self.app)
                      ^^^^^^^^^^^^^^^^^^^^^^^^^^^^
  File "/home/runner/workspace/.pythonlibs/lib/python3.11/site-packages/uvicorn/importer.py", line 19, in import_from_string
    module = importlib.import_module(module_str)
             ^^^^^^^^^^^^^^^^^^^^^^^^^^^^^^^^^^^
  File "/nix/store/clx0mcir7qw8zk36zbr4jra789g3knf6-python3-3.11.10/lib/python3.11/importlib/__init__.py", line 126, in import_module
    return _bootstrap._gcd_import(name[level:], package, level)
           ^^^^^^^^^^^^^^^^^^^^^^^^^^^^^^^^^^^^^^^^^^^^^^^^^^^^
  File "<frozen importlib._bootstrap>", line 1204, in _gcd_import
  File "<frozen importlib._bootstrap>", line 1176, in _find_and_load
  File "<frozen importlib._bootstrap>", line 1147, in _find_and_load_unlocked
  File "<frozen importlib._bootstrap>", line 690, in _load_unlocked
  File "<frozen importlib._bootstrap_external>", line 940, in exec_module
  File "<frozen importlib._bootstrap>", line 241, in _call_with_frames_removed
  File "/home/runner/workspace/main.py", line 9, in <module>
    from database import crud, schemas, get_db
  File "/home/runner/workspace/database/__init__.py", line 1, in <module>
    from .database import get_db, engine, SessionLocal, verify_database
  File "/home/runner/workspace/database/database.py", line 31, in <module>
    with engine.connect() as conn:
         ^^^^^^^^^^^^^^^^
  File "/home/runner/workspace/.pythonlibs/lib/python3.11/site-packages/sqlalchemy/engine/base.py", line 3278, in connect
    return self._connection_cls(self)
           ^^^^^^^^^^^^^^^^^^^^^^^^^^
  File "/home/runner/workspace/.pythonlibs/lib/python3.11/site-packages/sqlalchemy/engine/base.py", line 148, in __init__
    Connection._handle_dbapi_exception_noconnection(
  File "/home/runner/workspace/.pythonlibs/lib/python3.11/site-packages/sqlalchemy/engine/base.py", line 2442, in _handle_dbapi_exception_noconnection
    raise sqlalchemy_exception.with_traceback(exc_info[2]) from e
  File "/home/runner/workspace/.pythonlibs/lib/python3.11/site-packages/sqlalchemy/engine/base.py", line 146, in __init__
    self._dbapi_connection = engine.raw_connection()
                             ^^^^^^^^^^^^^^^^^^^^^^^
  File "/home/runner/workspace/.pythonlibs/lib/python3.11/site-packages/sqlalchemy/engine/base.py", line 3302, in raw_connection
    return self.pool.connect()
           ^^^^^^^^^^^^^^^^^^^
  File "/home/runner/workspace/.pythonlibs/lib/python3.11/site-packages/sqlalchemy/pool/base.py", line 449, in connect
    return _ConnectionFairy._checkout(self)
           ^^^^^^^^^^^^^^^^^^^^^^^^^^^^^^^^
  File "/home/runner/workspace/.pythonlibs/lib/python3.11/site-packages/sqlalchemy/pool/base.py", line 1263, in _checkout
    fairy = _ConnectionRecord.checkout(pool)
            ^^^^^^^^^^^^^^^^^^^^^^^^^^^^^^^^
  File "/home/runner/workspace/.pythonlibs/lib/python3.11/site-packages/sqlalchemy/pool/base.py", line 712, in checkout
    rec = pool._do_get()
          ^^^^^^^^^^^^^^
  File "/home/runner/workspace/.pythonlibs/lib/python3.11/site-packages/sqlalchemy/pool/impl.py", line 179, in _do_get
    with util.safe_reraise():
  File "/home/runner/workspace/.pythonlibs/lib/python3.11/site-packages/sqlalchemy/util/langhelpers.py", line 146, in __exit__
    raise exc_value.with_traceback(exc_tb)
  File "/home/runner/workspace/.pythonlibs/lib/python3.11/site-packages/sqlalchemy/pool/impl.py", line 177, in _do_get
    return self._create_connection()
           ^^^^^^^^^^^^^^^^^^^^^^^^^
  File "/home/runner/workspace/.pythonlibs/lib/python3.11/site-packages/sqlalchemy/pool/base.py", line 390, in _create_connection
    return _ConnectionRecord(self)
           ^^^^^^^^^^^^^^^^^^^^^^^
  File "/home/runner/workspace/.pythonlibs/lib/python3.11/site-packages/sqlalchemy/pool/base.py", line 674, in __init__
    self.__connect()
  File "/home/runner/workspace/.pythonlibs/lib/python3.11/site-packages/sqlalchemy/pool/base.py", line 900, in __connect
    with util.safe_reraise():
  File "/home/runner/workspace/.pythonlibs/lib/python3.11/site-packages/sqlalchemy/util/langhelpers.py", line 146, in __exit__
    raise exc_value.with_traceback(exc_tb)
  File "/home/runner/workspace/.pythonlibs/lib/python3.11/site-packages/sqlalchemy/pool/base.py", line 896, in __connect
    self.dbapi_connection = connection = pool._invoke_creator(self)
                                         ^^^^^^^^^^^^^^^^^^^^^^^^^^
  File "/home/runner/workspace/.pythonlibs/lib/python3.11/site-packages/sqlalchemy/engine/create.py", line 643, in connect
    return dialect.connect(*cargs, **cparams)
           ^^^^^^^^^^^^^^^^^^^^^^^^^^^^^^^^^^
  File "/home/runner/workspace/.pythonlibs/lib/python3.11/site-packages/sqlalchemy/engine/default.py", line 621, in connect
    return self.loaded_dbapi.connect(*cargs, **cparams)
           ^^^^^^^^^^^^^^^^^^^^^^^^^^^^^^^^^^^^^^^^^^^^
  File "/home/runner/workspace/.pythonlibs/lib/python3.11/site-packages/psycopg2/__init__.py", line 122, in connect
    conn = _connect(dsn, connection_factory=connection_factory, **kwasync)
           ^^^^^^^^^^^^^^^^^^^^^^^^^^^^^^^^^^^^^^^^^^^^^^^^^^^^^^^^^^^^^^^
sqlalchemy.exc.OperationalError: (psycopg2.OperationalError) connection to server at "ep-damp-art-a8ixdln.eastus2.azure.neon.tech" (52.167.188.143), port 5432 failed: ERROR:  password authentication failed for user 'neondb_owner'

(Background on this error at: https://sqlalche.me/e/20/e3q8)