INFO:     172.31.128.97:47772 - "OPTIONS /customers HTTP/1.1" 200 OK
{"timestamp": "2025-02-12T07:32:19.080553", "level": "INFO", "correlation_id": "6a90dea5-8881-46d9-8552-533a924a99b4", "logger": "TimesheetTracker", "message": "Incoming request", "context": {"correlation_id": "6a90dea5-8881-46d9-8552-533a924a99b4", "method": "POST", "url": "http://6ed7ce35-85b3-498b-9e9b-4d63631ed8e3-00-2owzgyvztotfg.worf.replit.dev/customers", "client_host": "172.31.128.97", "headers": {"host": "6ed7ce35-85b3-498b-9e9b-4d63631ed8e3-00-2owzgyvztotfg.worf.replit.dev", "user-agent": "Mozilla/5.0 (Windows NT 10.0; Win64; x64) AppleWebKit/537.36 (KHTML, like Gecko) Chrome/132.0.0.0 Safari/537.36 Edg/132.0.0.0", "content-length": "120", "accept": "application/json, text/plain, */*", "accept-encoding": "gzip, deflate, br, zstd", "accept-language": "en-US,en;q=0.9", "content-type": "application/json", "origin": "https://kzmgtm5ncqaltjbk8pjj.lite.vusercontent.net", "referer": "https://kzmgtm5ncqaltjbk8pjj.lite.vusercontent.net/", "sec-ch-ua": "\"Not A(Brand\";v=\"8\", \"Chromium\";v=\"132\", \"Microsoft Edge\";v=\"132\"", "sec-ch-ua-mobile": "?0", "sec-ch-ua-platform": "\"Windows\"", "sec-fetch-dest": "empty", "sec-fetch-mode": "cors", "sec-fetch-site": "cross-site", "x-forwarded-for": "67.11.111.13, 165.225.36.171, 10.83.8.29", "x-forwarded-proto": "https", "x-replit-user-bio": "", "x-replit-user-id": "", "x-replit-user-name": "", "x-replit-user-profile-image": "", "x-replit-user-roles": "", "x-replit-user-teams": "", "x-replit-user-url": ""}, "path_params": {}, "query_params": {}, "request_id": null, "path": "/customers"}}
{"timestamp": "2025-02-12T07:32:19.081637", "level": "DEBUG", "correlation_id": "6a90dea5-8881-46d9-8552-533a924a99b4", "logger": "TimesheetTracker", "message": "Database session created", "context": {}}
{"timestamp": "2025-02-12T07:32:19.084179", "level": "DEBUG", "correlation_id": "6a90dea5-8881-46d9-8552-533a924a99b4", "logger": "TimesheetTracker", "message": "CustomerService initialized with database session", "context": {}}
{"timestamp": "2025-02-12T07:32:19.084417", "level": "DEBUG", "correlation_id": "6a90dea5-8881-46d9-8552-533a924a99b4", "logger": "TimesheetTracker", "message": "Starting creation of customer with data: {'name': 'HEB', 'contact_email': 'heb@email.com', 'industry': 'F&B', 'status': 'active', 'address': 'IH-35', 'phone': '1234567890'}", "context": {}}
{"timestamp": "2025-02-12T07:32:19.170895", "level": "WARNING", "correlation_id": "6a90dea5-8881-46d9-8552-533a924a99b4", "logger": "TimesheetTracker", "message": "Customer with name HEB already exists", "context": {}}
{"timestamp": "2025-02-12T07:32:19.171158", "level": "ERROR", "correlation_id": "6a90dea5-8881-46d9-8552-533a924a99b4", "logger": "TimesheetTracker", "message": "Error creating customer: Customer with name HEB already exists", "context": {}}
{"timestamp": "2025-02-12T07:32:19.191198", "level": "ERROR", "correlation_id": "6a90dea5-8881-46d9-8552-533a924a99b4", "logger": "TimesheetTracker", "message": "Database session error: Customer with name HEB already exists", "context": {}}
{"timestamp": "2025-02-12T07:32:19.192762", "level": "ERROR", "correlation_id": "6a90dea5-8881-46d9-8552-533a924a99b4", "logger": "TimesheetTracker", "message": "Database session error details:", "context": {}, "exception": "Traceback (most recent call last):\n  File \"/home/runner/workspace/database/database.py\", line 151, in get_db\n    yield db\n  File \"/home/runner/workspace/.pythonlibs/lib/python3.11/site-packages/fastapi/concurrency.py\", line 27, in contextmanager_in_threadpool\n    yield await run_in_threadpool(cm.__enter__)\n  File \"/home/runner/workspace/.pythonlibs/lib/python3.11/site-packages/fastapi/routing.py\", line 301, in app\n    raw_response = await run_endpoint_function(\n                   ^^^^^^^^^^^^^^^^^^^^^^^^^^^^\n  File \"/home/runner/workspace/.pythonlibs/lib/python3.11/site-packages/fastapi/routing.py\", line 214, in run_endpoint_function\n    return await run_in_threadpool(dependant.call, **values)\n           ^^^^^^^^^^^^^^^^^^^^^^^^^^^^^^^^^^^^^^^^^^^^^^^^^\n  File \"/home/runner/workspace/.pythonlibs/lib/python3.11/site-packages/starlette/concurrency.py\", line 39, in run_in_threadpool\n    return await anyio.to_thread.run_sync(func, *args)\n           ^^^^^^^^^^^^^^^^^^^^^^^^^^^^^^^^^^^^^^^^^^^\n  File \"/home/runner/workspace/.pythonlibs/lib/python3.11/site-packages/anyio/to_thread.py\", line 56, in run_sync\n    return await get_async_backend().run_sync_in_worker_thread(\n           ^^^^^^^^^^^^^^^^^^^^^^^^^^^^^^^^^^^^^^^^^^^^^^^^^^^^\n  File \"/home/runner/workspace/.pythonlibs/lib/python3.11/site-packages/anyio/_backends/_asyncio.py\", line 2505, in run_sync_in_worker_thread\n    return await future\n           ^^^^^^^^^^^^\n  File \"/home/runner/workspace/.pythonlibs/lib/python3.11/site-packages/anyio/_backends/_asyncio.py\", line 1005, in run\n    result = context.run(func, *args)\n             ^^^^^^^^^^^^^^^^^^^^^^^^\n  File \"/home/runner/workspace/main.py\", line 228, in create_customer\n    return service.create_customer(customer)\n           ^^^^^^^^^^^^^^^^^^^^^^^^^^^^^^^^^\n  File \"/home/runner/workspace/services/customer_service.py\", line 26, in create_customer\n    raise ValueError(f\"Customer with name {customer.name} already exists\")\nValueError: Customer with name HEB already exists"}
{"timestamp": "2025-02-12T07:32:19.193455", "level": "DEBUG", "correlation_id": "6a90dea5-8881-46d9-8552-533a924a99b4", "logger": "TimesheetTracker", "message": "Database session closed", "context": {}}
{"timestamp": "2025-02-12T07:32:19.195555", "level": "ERROR", "correlation_id": "6a90dea5-8881-46d9-8552-533a924a99b4", "logger": "TimesheetTracker", "message": "Request failed with exception", "context": {"correlation_id": "6a90dea5-8881-46d9-8552-533a924a99b4", "error_type": "ValueError", "error_message": "Customer with name HEB already exists", "traceback": "Traceback (most recent call last):\n  File \"/home/runner/workspace/.pythonlibs/lib/python3.11/site-packages/anyio/streams/memory.py\", line 111, in receive\n    return self.receive_nowait()\n           ^^^^^^^^^^^^^^^^^^^^^\n  File \"/home/runner/workspace/.pythonlibs/lib/python3.11/site-packages/anyio/streams/memory.py\", line 106, in receive_nowait\n    raise WouldBlock\nanyio.WouldBlock\n\nDuring handling of the above exception, another exception occurred:\n\nTraceback (most recent call last):\n  File \"/home/runner/workspace/.pythonlibs/lib/python3.11/site-packages/anyio/streams/memory.py\", line 124, in receive\n    return receiver.item\n           ^^^^^^^^^^^^^\nAttributeError: 'MemoryObjectItemReceiver' object has no attribute 'item'\n\nDuring handling of the above exception, another exception occurred:\n\nTraceback (most recent call last):\n  File \"/home/runner/workspace/.pythonlibs/lib/python3.11/site-packages/starlette/middleware/base.py\", line 157, in call_next\n    message = await recv_stream.receive()\n              ^^^^^^^^^^^^^^^^^^^^^^^^^^^\n  File \"/home/runner/workspace/.pythonlibs/lib/python3.11/site-packages/anyio/streams/memory.py\", line 126, in receive\n    raise EndOfStream\nanyio.EndOfStream\n\nDuring handling of the above exception, another exception occurred:\n\nTraceback (most recent call last):\n  File \"/home/runner/workspace/utils/middleware.py\", line 45, in logging_middleware\n    response = await call_next(request)\n               ^^^^^^^^^^^^^^^^^^^^^^^^\n  File \"/home/runner/workspace/.pythonlibs/lib/python3.11/site-packages/starlette/middleware/base.py\", line 163, in call_next\n    raise app_exc\n  File \"/home/runner/workspace/.pythonlibs/lib/python3.11/site-packages/starlette/middleware/base.py\", line 149, in coro\n    await self.app(scope, receive_or_disconnect, send_no_error)\n  File \"/home/runner/workspace/.pythonlibs/lib/python3.11/site-packages/starlette/middleware/cors.py\", line 93, in __call__\n    await self.simple_response(scope, receive, send, request_headers=headers)\n  File \"/home/runner/workspace/.pythonlibs/lib/python3.11/site-packages/starlette/middleware/cors.py\", line 144, in simple_response\n    await self.app(scope, receive, send)\n  File \"/home/runner/workspace/.pythonlibs/lib/python3.11/site-packages/starlette/middleware/exceptions.py\", line 62, in __call__\n    await wrap_app_handling_exceptions(self.app, conn)(scope, receive, send)\n  File \"/home/runner/workspace/.pythonlibs/lib/python3.11/site-packages/starlette/_exception_handler.py\", line 53, in wrapped_app\n    raise exc\n  File \"/home/runner/workspace/.pythonlibs/lib/python3.11/site-packages/starlette/_exception_handler.py\", line 42, in wrapped_app\n    await app(scope, receive, sender)\n  File \"/home/runner/workspace/.pythonlibs/lib/python3.11/site-packages/starlette/routing.py\", line 715, in __call__\n    await self.middleware_stack(scope, receive, send)\n  File \"/home/runner/workspace/.pythonlibs/lib/python3.11/site-packages/starlette/routing.py\", line 735, in app\n    await route.handle(scope, receive, send)\n  File \"/home/runner/workspace/.pythonlibs/lib/python3.11/site-packages/starlette/routing.py\", line 288, in handle\n    await self.app(scope, receive, send)\n  File \"/home/runner/workspace/.pythonlibs/lib/python3.11/site-packages/starlette/routing.py\", line 76, in app\n    await wrap_app_handling_exceptions(app, request)(scope, receive, send)\n  File \"/home/runner/workspace/.pythonlibs/lib/python3.11/site-packages/starlette/_exception_handler.py\", line 53, in wrapped_app\n    raise exc\n  File \"/home/runner/workspace/.pythonlibs/lib/python3.11/site-packages/starlette/_exception_handler.py\", line 42, in wrapped_app\n    await app(scope, receive, sender)\n  File \"/home/runner/workspace/.pythonlibs/lib/python3.11/site-packages/starlette/routing.py\", line 73, in app\n    response = await f(request)\n               ^^^^^^^^^^^^^^^^\n  File \"/home/runner/workspace/.pythonlibs/lib/python3.11/site-packages/fastapi/routing.py\", line 301, in app\n    raw_response = await run_endpoint_function(\n                   ^^^^^^^^^^^^^^^^^^^^^^^^^^^^\n  File \"/home/runner/workspace/.pythonlibs/lib/python3.11/site-packages/fastapi/routing.py\", line 214, in run_endpoint_function\n    return await run_in_threadpool(dependant.call, **values)\n           ^^^^^^^^^^^^^^^^^^^^^^^^^^^^^^^^^^^^^^^^^^^^^^^^^\n  File \"/home/runner/workspace/.pythonlibs/lib/python3.11/site-packages/starlette/concurrency.py\", line 39, in run_in_threadpool\n    return await anyio.to_thread.run_sync(func, *args)\n           ^^^^^^^^^^^^^^^^^^^^^^^^^^^^^^^^^^^^^^^^^^^\n  File \"/home/runner/workspace/.pythonlibs/lib/python3.11/site-packages/anyio/to_thread.py\", line 56, in run_sync\n    return await get_async_backend().run_sync_in_worker_thread(\n           ^^^^^^^^^^^^^^^^^^^^^^^^^^^^^^^^^^^^^^^^^^^^^^^^^^^^\n  File \"/home/runner/workspace/.pythonlibs/lib/python3.11/site-packages/anyio/_backends/_asyncio.py\", line 2505, in run_sync_in_worker_thread\n    return await future\n           ^^^^^^^^^^^^\n  File \"/home/runner/workspace/.pythonlibs/lib/python3.11/site-packages/anyio/_backends/_asyncio.py\", line 1005, in run\n    result = context.run(func, *args)\n             ^^^^^^^^^^^^^^^^^^^^^^^^\n  File \"/home/runner/workspace/main.py\", line 228, in create_customer\n    return service.create_customer(customer)\n           ^^^^^^^^^^^^^^^^^^^^^^^^^^^^^^^^^\n  File \"/home/runner/workspace/services/customer_service.py\", line 26, in create_customer\n    raise ValueError(f\"Customer with name {customer.name} already exists\")\nValueError: Customer with name HEB already exists\n", "request_method": "POST", "request_url": "http://6ed7ce35-85b3-498b-9e9b-4d63631ed8e3-00-2owzgyvztotfg.worf.replit.dev/customers", "request_headers": {"host": "6ed7ce35-85b3-498b-9e9b-4d63631ed8e3-00-2owzgyvztotfg.worf.replit.dev", "user-agent": "Mozilla/5.0 (Windows NT 10.0; Win64; x64) AppleWebKit/537.36 (KHTML, like Gecko) Chrome/132.0.0.0 Safari/537.36 Edg/132.0.0.0", "content-length": "120", "accept": "application/json, text/plain, */*", "accept-encoding": "gzip, deflate, br, zstd", "accept-language": "en-US,en;q=0.9", "content-type": "application/json", "origin": "https://kzmgtm5ncqaltjbk8pjj.lite.vusercontent.net", "referer": "https://kzmgtm5ncqaltjbk8pjj.lite.vusercontent.net/", "sec-ch-ua": "\"Not A(Brand\";v=\"8\", \"Chromium\";v=\"132\", \"Microsoft Edge\";v=\"132\"", "sec-ch-ua-mobile": "?0", "sec-ch-ua-platform": "\"Windows\"", "sec-fetch-dest": "empty", "sec-fetch-mode": "cors", "sec-fetch-site": "cross-site", "x-forwarded-for": "67.11.111.13, 165.225.36.171, 10.83.8.29", "x-forwarded-proto": "https", "x-replit-user-bio": "", "x-replit-user-id": "", "x-replit-user-name": "", "x-replit-user-profile-image": "", "x-replit-user-roles": "", "x-replit-user-teams": "", "x-replit-user-url": ""}, "client_host": "172.31.128.97", "query_params": {}, "path_params": {}, "path": "/customers", "origin": "https://kzmgtm5ncqaltjbk8pjj.lite.vusercontent.net", "cors_method": null, "cors_headers": null}}
{"timestamp": "2025-02-12T07:32:19.196187", "level": "DEBUG", "correlation_id": "6a90dea5-8881-46d9-8552-533a924a99b4", "logger": "TimesheetTracker", "message": {"message": "Adding CORS headers to response", "timestamp": "2025-02-12T07:32:19.195991", "context": {"correlation_id": "6a90dea5-8881-46d9-8552-533a924a99b4", "method": "POST", "path": "/customers", "status_code": 500}}, "context": {}}
INFO:     172.31.128.97:47772 - "POST /customers HTTP/1.1" 500 Internal Server Error