INFO:     172.31.128.43:50026 - "OPTIONS /projects/Aspers_PA HTTP/1.1" 200 OK
{"timestamp": "2025-02-12T03:25:26.875478", "level": "INFO", "correlation_id": "7d84ecfd-7f1f-4793-9026-6348c3ba9986", "logger": "TimesheetTracker", "message": "Incoming request", "context": {"correlation_id": "7d84ecfd-7f1f-4793-9026-6348c3ba9986", "method": "PUT", "url": "http://6ed7ce35-85b3-498b-9e9b-4d63631ed8e3-00-2owzgyvztotfg.worf.replit.dev/projects/Aspers_PA", "client_host": "172.31.128.43", "headers": {"host": "6ed7ce35-85b3-498b-9e9b-4d63631ed8e3-00-2owzgyvztotfg.worf.replit.dev", "user-agent": "Mozilla/5.0 (Windows NT 10.0; Win64; x64) AppleWebKit/537.36 (KHTML, like Gecko) Chrome/132.0.0.0 Safari/537.36 Edg/132.0.0.0", "content-length": "249", "accept": "application/json, text/plain, */*", "accept-encoding": "gzip, deflate, br, zstd", "accept-language": "en-US,en;q=0.9", "content-type": "application/json", "origin": "https://kzmp76owp04myy2i31bn.lite.vusercontent.net", "referer": "https://kzmp76owp04myy2i31bn.lite.vusercontent.net/", "sec-ch-ua": "\"Not A(Brand\";v=\"8\", \"Chromium\";v=\"132\", \"Microsoft Edge\";v=\"132\"", "sec-ch-ua-mobile": "?0", "sec-ch-ua-platform": "\"Windows\"", "sec-fetch-dest": "empty", "sec-fetch-mode": "cors", "sec-fetch-site": "cross-site", "x-forwarded-for": "67.11.111.13, 165.225.36.171, 10.83.3.152", "x-forwarded-proto": "https", "x-replit-user-bio": "", "x-replit-user-id": "", "x-replit-user-name": "", "x-replit-user-profile-image": "", "x-replit-user-roles": "", "x-replit-user-teams": "", "x-replit-user-url": ""}, "path_params": {}, "query_params": {}, "request_id": null, "path": "/projects/Aspers_PA"}}
{"timestamp": "2025-02-12T03:25:26.876944", "level": "DEBUG", "correlation_id": "7d84ecfd-7f1f-4793-9026-6348c3ba9986", "logger": "TimesheetTracker", "message": "Database session created", "context": {}}
{"timestamp": "2025-02-12T03:25:26.877696", "level": "DEBUG", "correlation_id": "7d84ecfd-7f1f-4793-9026-6348c3ba9986", "logger": "TimesheetTracker", "message": "ProjectRepository initialized", "context": {}}
{"timestamp": "2025-02-12T03:25:26.877863", "level": "DEBUG", "correlation_id": "7d84ecfd-7f1f-4793-9026-6348c3ba9986", "logger": "TimesheetTracker", "message": "ProjectService initialized with database session", "context": {}}
{"timestamp": "2025-02-12T03:25:26.878018", "level": "DEBUG", "correlation_id": "7d84ecfd-7f1f-4793-9026-6348c3ba9986", "logger": "TimesheetTracker", "message": "Attempting to update project Aspers_PA", "context": {}}
{"timestamp": "2025-02-12T03:25:26.878166", "level": "DEBUG", "correlation_id": "7d84ecfd-7f1f-4793-9026-6348c3ba9986", "logger": "TimesheetTracker", "message": "Fetching project with ID: Aspers_PA", "context": {}}
{"timestamp": "2025-02-12T03:25:26.878330", "level": "DEBUG", "correlation_id": "7d84ecfd-7f1f-4793-9026-6348c3ba9986", "logger": "TimesheetTracker", "message": "Fetching project with ID: Aspers_PA", "context": {}}
{"timestamp": "2025-02-12T03:25:26.938022", "level": "INFO", "correlation_id": "7d84ecfd-7f1f-4793-9026-6348c3ba9986", "logger": "TimesheetTracker", "message": "Found project: Aspers_PA", "context": {}}
{"timestamp": "2025-02-12T03:25:26.938526", "level": "DEBUG", "correlation_id": "7d84ecfd-7f1f-4793-9026-6348c3ba9986", "logger": "TimesheetTracker", "message": "Updating project: Aspers_PA", "context": {}}
{"timestamp": "2025-02-12T03:25:26.979857", "level": "ERROR", "correlation_id": "7d84ecfd-7f1f-4793-9026-6348c3ba9986", "logger": "TimesheetTracker", "message": "Error updating project: (psycopg2.errors.ForeignKeyViolation) insert or update on table \"projects\" violates foreign key constraint \"projects_project_manager_fkey\"\nDETAIL:  Key (project_manager)=(-) is not present in table \"project_managers\".\n\n[SQL: UPDATE projects SET project_manager=%(project_manager)s, updated_at=now() WHERE projects.id = %(projects_id)s]\n[parameters: {'project_manager': '-', 'projects_id': 5}]\n(Background on this error at: https://sqlalche.me/e/20/gkpj)", "context": {}}
{"timestamp": "2025-02-12T03:25:26.980269", "level": "ERROR", "correlation_id": "7d84ecfd-7f1f-4793-9026-6348c3ba9986", "logger": "TimesheetTracker", "message": "Error updating project Aspers_PA: (psycopg2.errors.ForeignKeyViolation) insert or update on table \"projects\" violates foreign key constraint \"projects_project_manager_fkey\"\nDETAIL:  Key (project_manager)=(-) is not present in table \"project_managers\".\n\n[SQL: UPDATE projects SET project_manager=%(project_manager)s, updated_at=now() WHERE projects.id = %(projects_id)s]\n[parameters: {'project_manager': '-', 'projects_id': 5}]\n(Background on this error at: https://sqlalche.me/e/20/gkpj)", "context": {}}
{"timestamp": "2025-02-12T03:25:26.980900", "level": "ERROR", "correlation_id": "7d84ecfd-7f1f-4793-9026-6348c3ba9986", "logger": "TimesheetTracker", "message": "Database session error: (psycopg2.errors.ForeignKeyViolation) insert or update on table \"projects\" violates foreign key constraint \"projects_project_manager_fkey\"\nDETAIL:  Key (project_manager)=(-) is not present in table \"project_managers\".\n\n[SQL: UPDATE projects SET project_manager=%(project_manager)s, updated_at=now() WHERE projects.id = %(projects_id)s]\n[parameters: {'project_manager': '-', 'projects_id': 5}]\n(Background on this error at: https://sqlalche.me/e/20/gkpj)", "context": {}}
{"timestamp": "2025-02-12T03:25:26.990995", "level": "ERROR", "correlation_id": "7d84ecfd-7f1f-4793-9026-6348c3ba9986", "logger": "TimesheetTracker", "message": "Database session error details:", "context": {}, "exception": "Traceback (most recent call last):\n  File \"/home/runner/workspace/.pythonlibs/lib/python3.11/site-packages/sqlalchemy/engine/base.py\", line 1967, in _exec_single_context\n    self.dialect.do_execute(\n  File \"/home/runner/workspace/.pythonlibs/lib/python3.11/site-packages/sqlalchemy/engine/default.py\", line 941, in do_execute\n    cursor.execute(statement, parameters)\npsycopg2.errors.ForeignKeyViolation: insert or update on table \"projects\" violates foreign key constraint \"projects_project_manager_fkey\"\nDETAIL:  Key (project_manager)=(-) is not present in table \"project_managers\".\n\n\nThe above exception was the direct cause of the following exception:\n\nTraceback (most recent call last):\n  File \"/home/runner/workspace/database/database.py\", line 151, in get_db\n    yield db\n  File \"/home/runner/workspace/.pythonlibs/lib/python3.11/site-packages/fastapi/concurrency.py\", line 27, in contextmanager_in_threadpool\n    yield await run_in_threadpool(cm.__enter__)\n  File \"/home/runner/workspace/.pythonlibs/lib/python3.11/site-packages/fastapi/routing.py\", line 301, in app\n    raw_response = await run_endpoint_function(\n                   ^^^^^^^^^^^^^^^^^^^^^^^^^^^^\n  File \"/home/runner/workspace/.pythonlibs/lib/python3.11/site-packages/fastapi/routing.py\", line 214, in run_endpoint_function\n    return await run_in_threadpool(dependant.call, **values)\n           ^^^^^^^^^^^^^^^^^^^^^^^^^^^^^^^^^^^^^^^^^^^^^^^^^\n  File \"/home/runner/workspace/.pythonlibs/lib/python3.11/site-packages/starlette/concurrency.py\", line 39, in run_in_threadpool\n    return await anyio.to_thread.run_sync(func, *args)\n           ^^^^^^^^^^^^^^^^^^^^^^^^^^^^^^^^^^^^^^^^^^^\n  File \"/home/runner/workspace/.pythonlibs/lib/python3.11/site-packages/anyio/to_thread.py\", line 56, in run_sync\n    return await get_async_backend().run_sync_in_worker_thread(\n           ^^^^^^^^^^^^^^^^^^^^^^^^^^^^^^^^^^^^^^^^^^^^^^^^^^^^\n  File \"/home/runner/workspace/.pythonlibs/lib/python3.11/site-packages/anyio/_backends/_asyncio.py\", line 2505, in run_sync_in_worker_thread\n    return await future\n           ^^^^^^^^^^^^\n  File \"/home/runner/workspace/.pythonlibs/lib/python3.11/site-packages/anyio/_backends/_asyncio.py\", line 1005, in run\n    result = context.run(func, *args)\n             ^^^^^^^^^^^^^^^^^^^^^^^^\n  File \"/home/runner/workspace/main.py\", line 180, in update_project\n    return service.update_project(project_id, project)\n           ^^^^^^^^^^^^^^^^^^^^^^^^^^^^^^^^^^^^^^^^^^^\n  File \"/home/runner/workspace/services/project_service.py\", line 180, in update_project\n    updated_project = self.project_repo.update(self.db, existing_project)\n                      ^^^^^^^^^^^^^^^^^^^^^^^^^^^^^^^^^^^^^^^^^^^^^^^^^^^\n  File \"/home/runner/workspace/database/project_repository.py\", line 55, in update\n    db.commit()\n  File \"/home/runner/workspace/.pythonlibs/lib/python3.11/site-packages/sqlalchemy/orm/session.py\", line 2028, in commit\n    trans.commit(_to_root=True)\n  File \"<string>\", line 2, in commit\n  File \"/home/runner/workspace/.pythonlibs/lib/python3.11/site-packages/sqlalchemy/orm/state_changes.py\", line 139, in _go\n    ret_value = fn(self, *arg, **kw)\n                ^^^^^^^^^^^^^^^^^^^^\n  File \"/home/runner/workspace/.pythonlibs/lib/python3.11/site-packages/sqlalchemy/orm/session.py\", line 1313, in commit\n    self._prepare_impl()\n  File \"<string>\", line 2, in _prepare_impl\n  File \"/home/runner/workspace/.pythonlibs/lib/python3.11/site-packages/sqlalchemy/orm/state_changes.py\", line 139, in _go\n    ret_value = fn(self, *arg, **kw)\n                ^^^^^^^^^^^^^^^^^^^^\n  File \"/home/runner/workspace/.pythonlibs/lib/python3.11/site-packages/sqlalchemy/orm/session.py\", line 1288, in _prepare_impl\n    self.session.flush()\n  File \"/home/runner/workspace/.pythonlibs/lib/python3.11/site-packages/sqlalchemy/orm/session.py\", line 4352, in flush\n    self._flush(objects)\n  File \"/home/runner/workspace/.pythonlibs/lib/python3.11/site-packages/sqlalchemy/orm/session.py\", line 4487, in _flush\n    with util.safe_reraise():\n  File \"/home/runner/workspace/.pythonlibs/lib/python3.11/site-packages/sqlalchemy/util/langhelpers.py\", line 146, in __exit__\n    raise exc_value.with_traceback(exc_tb)\n  File \"/home/runner/workspace/.pythonlibs/lib/python3.11/site-packages/sqlalchemy/orm/session.py\", line 4448, in _flush\n    flush_context.execute()\n  File \"/home/runner/workspace/.pythonlibs/lib/python3.11/site-packages/sqlalchemy/orm/unitofwork.py\", line 466, in execute\n    rec.execute(self)\n  File \"/home/runner/workspace/.pythonlibs/lib/python3.11/site-packages/sqlalchemy/orm/unitofwork.py\", line 642, in execute\n    util.preloaded.orm_persistence.save_obj(\n  File \"/home/runner/workspace/.pythonlibs/lib/python3.11/site-packages/sqlalchemy/orm/persistence.py\", line 85, in save_obj\n    _emit_update_statements(\n  File \"/home/runner/workspace/.pythonlibs/lib/python3.11/site-packages/sqlalchemy/orm/persistence.py\", line 912, in _emit_update_statements\n    c = connection.execute(\n        ^^^^^^^^^^^^^^^^^^^\n  File \"/home/runner/workspace/.pythonlibs/lib/python3.11/site-packages/sqlalchemy/engine/base.py\", line 1418, in execute\n    return meth(\n           ^^^^^\n  File \"/home/runner/workspace/.pythonlibs/lib/python3.11/site-packages/sqlalchemy/sql/elements.py\", line 515, in _execute_on_connection\n    return connection._execute_clauseelement(\n           ^^^^^^^^^^^^^^^^^^^^^^^^^^^^^^^^^^\n  File \"/home/runner/workspace/.pythonlibs/lib/python3.11/site-packages/sqlalchemy/engine/base.py\", line 1640, in _execute_clauseelement\n    ret = self._execute_context(\n          ^^^^^^^^^^^^^^^^^^^^^^\n  File \"/home/runner/workspace/.pythonlibs/lib/python3.11/site-packages/sqlalchemy/engine/base.py\", line 1846, in _execute_context\n    return self._exec_single_context(\n           ^^^^^^^^^^^^^^^^^^^^^^^^^^\n  File \"/home/runner/workspace/.pythonlibs/lib/python3.11/site-packages/sqlalchemy/engine/base.py\", line 1986, in _exec_single_context\n    self._handle_dbapi_exception(\n  File \"/home/runner/workspace/.pythonlibs/lib/python3.11/site-packages/sqlalchemy/engine/base.py\", line 2355, in _handle_dbapi_exception\n    raise sqlalchemy_exception.with_traceback(exc_info[2]) from e\n  File \"/home/runner/workspace/.pythonlibs/lib/python3.11/site-packages/sqlalchemy/engine/base.py\", line 1967, in _exec_single_context\n    self.dialect.do_execute(\n  File \"/home/runner/workspace/.pythonlibs/lib/python3.11/site-packages/sqlalchemy/engine/default.py\", line 941, in do_execute\n    cursor.execute(statement, parameters)\nsqlalchemy.exc.IntegrityError: (psycopg2.errors.ForeignKeyViolation) insert or update on table \"projects\" violates foreign key constraint \"projects_project_manager_fkey\"\nDETAIL:  Key (project_manager)=(-) is not present in table \"project_managers\".\n\n[SQL: UPDATE projects SET project_manager=%(project_manager)s, updated_at=now() WHERE projects.id = %(projects_id)s]\n[parameters: {'project_manager': '-', 'projects_id': 5}]\n(Background on this error at: https://sqlalche.me/e/20/gkpj)"}
{"timestamp": "2025-02-12T03:25:26.996278", "level": "DEBUG", "correlation_id": "7d84ecfd-7f1f-4793-9026-6348c3ba9986", "logger": "TimesheetTracker", "message": "Database session closed", "context": {}}
{"timestamp": "2025-02-12T03:25:27.005217", "level": "ERROR", "correlation_id": "7d84ecfd-7f1f-4793-9026-6348c3ba9986", "logger": "TimesheetTracker", "message": "Request failed with exception", "context": {"correlation_id": "7d84ecfd-7f1f-4793-9026-6348c3ba9986", "error_type": "IntegrityError", "error_message": "(psycopg2.errors.ForeignKeyViolation) insert or update on table \"projects\" violates foreign key constraint \"projects_project_manager_fkey\"\nDETAIL:  Key (project_manager)=(-) is not present in table \"project_managers\".\n\n[SQL: UPDATE projects SET project_manager=%(project_manager)s, updated_at=now() WHERE projects.id = %(projects_id)s]\n[parameters: {'project_manager': '-', 'projects_id': 5}]\n(Background on this error at: https://sqlalche.me/e/20/gkpj)", "traceback": "Traceback (most recent call last):\n  File \"/home/runner/workspace/.pythonlibs/lib/python3.11/site-packages/sqlalchemy/engine/base.py\", line 1967, in _exec_single_context\n    self.dialect.do_execute(\n  File \"/home/runner/workspace/.pythonlibs/lib/python3.11/site-packages/sqlalchemy/engine/default.py\", line 941, in do_execute\n    cursor.execute(statement, parameters)\npsycopg2.errors.ForeignKeyViolation: insert or update on table \"projects\" violates foreign key constraint \"projects_project_manager_fkey\"\nDETAIL:  Key (project_manager)=(-) is not present in table \"project_managers\".\n\n\nThe above exception was the direct cause of the following exception:\n\nTraceback (most recent call last):\n  File \"/home/runner/workspace/utils/middleware.py\", line 45, in logging_middleware\n    response = await call_next(request)\n               ^^^^^^^^^^^^^^^^^^^^^^^^\n  File \"/home/runner/workspace/.pythonlibs/lib/python3.11/site-packages/starlette/middleware/base.py\", line 163, in call_next\n    raise app_exc\n  File \"/home/runner/workspace/.pythonlibs/lib/python3.11/site-packages/starlette/middleware/base.py\", line 149, in coro\n    await self.app(scope, receive_or_disconnect, send_no_error)\n  File \"/home/runner/workspace/.pythonlibs/lib/python3.11/site-packages/starlette/middleware/cors.py\", line 93, in __call__\n    await self.simple_response(scope, receive, send, request_headers=headers)\n  File \"/home/runner/workspace/.pythonlibs/lib/python3.11/site-packages/starlette/middleware/cors.py\", line 144, in simple_response\n    await self.app(scope, receive, send)\n  File \"/home/runner/workspace/.pythonlibs/lib/python3.11/site-packages/starlette/middleware/exceptions.py\", line 62, in __call__\n    await wrap_app_handling_exceptions(self.app, conn)(scope, receive, send)\n  File \"/home/runner/workspace/.pythonlibs/lib/python3.11/site-packages/starlette/_exception_handler.py\", line 53, in wrapped_app\n    raise exc\n  File \"/home/runner/workspace/.pythonlibs/lib/python3.11/site-packages/starlette/_exception_handler.py\", line 42, in wrapped_app\n    await app(scope, receive, sender)\n  File \"/home/runner/workspace/.pythonlibs/lib/python3.11/site-packages/starlette/routing.py\", line 715, in __call__\n    await self.middleware_stack(scope, receive, send)\n  File \"/home/runner/workspace/.pythonlibs/lib/python3.11/site-packages/starlette/routing.py\", line 735, in app\n    await route.handle(scope, receive, send)\n  File \"/home/runner/workspace/.pythonlibs/lib/python3.11/site-packages/starlette/routing.py\", line 288, in handle\n    await self.app(scope, receive, send)\n  File \"/home/runner/workspace/.pythonlibs/lib/python3.11/site-packages/starlette/routing.py\", line 76, in app\n    await wrap_app_handling_exceptions(app, request)(scope, receive, send)\n  File \"/home/runner/workspace/.pythonlibs/lib/python3.11/site-packages/starlette/_exception_handler.py\", line 53, in wrapped_app\n    raise exc\n  File \"/home/runner/workspace/.pythonlibs/lib/python3.11/site-packages/starlette/_exception_handler.py\", line 42, in wrapped_app\n    await app(scope, receive, sender)\n  File \"/home/runner/workspace/.pythonlibs/lib/python3.11/site-packages/starlette/routing.py\", line 73, in app\n    response = await f(request)\n               ^^^^^^^^^^^^^^^^\n  File \"/home/runner/workspace/.pythonlibs/lib/python3.11/site-packages/fastapi/routing.py\", line 301, in app\n    raw_response = await run_endpoint_function(\n                   ^^^^^^^^^^^^^^^^^^^^^^^^^^^^\n  File \"/home/runner/workspace/.pythonlibs/lib/python3.11/site-packages/fastapi/routing.py\", line 214, in run_endpoint_function\n    return await run_in_threadpool(dependant.call, **values)\n           ^^^^^^^^^^^^^^^^^^^^^^^^^^^^^^^^^^^^^^^^^^^^^^^^^\n  File \"/home/runner/workspace/.pythonlibs/lib/python3.11/site-packages/starlette/concurrency.py\", line 39, in run_in_threadpool\n    return await anyio.to_thread.run_sync(func, *args)\n           ^^^^^^^^^^^^^^^^^^^^^^^^^^^^^^^^^^^^^^^^^^^\n  File \"/home/runner/workspace/.pythonlibs/lib/python3.11/site-packages/anyio/to_thread.py\", line 56, in run_sync\n    return await get_async_backend().run_sync_in_worker_thread(\n           ^^^^^^^^^^^^^^^^^^^^^^^^^^^^^^^^^^^^^^^^^^^^^^^^^^^^\n  File \"/home/runner/workspace/.pythonlibs/lib/python3.11/site-packages/anyio/_backends/_asyncio.py\", line 2505, in run_sync_in_worker_thread\n    return await future\n           ^^^^^^^^^^^^\n  File \"/home/runner/workspace/.pythonlibs/lib/python3.11/site-packages/anyio/_backends/_asyncio.py\", line 1005, in run\n    result = context.run(func, *args)\n             ^^^^^^^^^^^^^^^^^^^^^^^^\n  File \"/home/runner/workspace/main.py\", line 180, in update_project\n    return service.update_project(project_id, project)\n           ^^^^^^^^^^^^^^^^^^^^^^^^^^^^^^^^^^^^^^^^^^^\n  File \"/home/runner/workspace/services/project_service.py\", line 180, in update_project\n    updated_project = self.project_repo.update(self.db, existing_project)\n                      ^^^^^^^^^^^^^^^^^^^^^^^^^^^^^^^^^^^^^^^^^^^^^^^^^^^\n  File \"/home/runner/workspace/database/project_repository.py\", line 55, in update\n    db.commit()\n  File \"/home/runner/workspace/.pythonlibs/lib/python3.11/site-packages/sqlalchemy/orm/session.py\", line 2028, in commit\n    trans.commit(_to_root=True)\n  File \"<string>\", line 2, in commit\n  File \"/home/runner/workspace/.pythonlibs/lib/python3.11/site-packages/sqlalchemy/orm/state_changes.py\", line 139, in _go\n    ret_value = fn(self, *arg, **kw)\n                ^^^^^^^^^^^^^^^^^^^^\n  File \"/home/runner/workspace/.pythonlibs/lib/python3.11/site-packages/sqlalchemy/orm/session.py\", line 1313, in commit\n    self._prepare_impl()\n  File \"<string>\", line 2, in _prepare_impl\n  File \"/home/runner/workspace/.pythonlibs/lib/python3.11/site-packages/sqlalchemy/orm/state_changes.py\", line 139, in _go\n    ret_value = fn(self, *arg, **kw)\n                ^^^^^^^^^^^^^^^^^^^^\n  File \"/home/runner/workspace/.pythonlibs/lib/python3.11/site-packages/sqlalchemy/orm/session.py\", line 1288, in _prepare_impl\n    self.session.flush()\n  File \"/home/runner/workspace/.pythonlibs/lib/python3.11/site-packages/sqlalchemy/orm/session.py\", line 4352, in flush\n    self._flush(objects)\n  File \"/home/runner/workspace/.pythonlibs/lib/python3.11/site-packages/sqlalchemy/orm/session.py\", line 4487, in _flush\n    with util.safe_reraise():\n  File \"/home/runner/workspace/.pythonlibs/lib/python3.11/site-packages/sqlalchemy/util/langhelpers.py\", line 146, in __exit__\n    raise exc_value.with_traceback(exc_tb)\n  File \"/home/runner/workspace/.pythonlibs/lib/python3.11/site-packages/sqlalchemy/orm/session.py\", line 4448, in _flush\n    flush_context.execute()\n  File \"/home/runner/workspace/.pythonlibs/lib/python3.11/site-packages/sqlalchemy/orm/unitofwork.py\", line 466, in execute\n    rec.execute(self)\n  File \"/home/runner/workspace/.pythonlibs/lib/python3.11/site-packages/sqlalchemy/orm/unitofwork.py\", line 642, in execute\n    util.preloaded.orm_persistence.save_obj(\n  File \"/home/runner/workspace/.pythonlibs/lib/python3.11/site-packages/sqlalchemy/orm/persistence.py\", line 85, in save_obj\n    _emit_update_statements(\n  File \"/home/runner/workspace/.pythonlibs/lib/python3.11/site-packages/sqlalchemy/orm/persistence.py\", line 912, in _emit_update_statements\n    c = connection.execute(\n        ^^^^^^^^^^^^^^^^^^^\n  File \"/home/runner/workspace/.pythonlibs/lib/python3.11/site-packages/sqlalchemy/engine/base.py\", line 1418, in execute\n    return meth(\n           ^^^^^\n  File \"/home/runner/workspace/.pythonlibs/lib/python3.11/site-packages/sqlalchemy/sql/elements.py\", line 515, in _execute_on_connection\n    return connection._execute_clauseelement(\n           ^^^^^^^^^^^^^^^^^^^^^^^^^^^^^^^^^^\n  File \"/home/runner/workspace/.pythonlibs/lib/python3.11/site-packages/sqlalchemy/engine/base.py\", line 1640, in _execute_clauseelement\n    ret = self._execute_context(\n          ^^^^^^^^^^^^^^^^^^^^^^\n  File \"/home/runner/workspace/.pythonlibs/lib/python3.11/site-packages/sqlalchemy/engine/base.py\", line 1846, in _execute_context\n    return self._exec_single_context(\n           ^^^^^^^^^^^^^^^^^^^^^^^^^^\n  File \"/home/runner/workspace/.pythonlibs/lib/python3.11/site-packages/sqlalchemy/engine/base.py\", line 1986, in _exec_single_context\n    self._handle_dbapi_exception(\n  File \"/home/runner/workspace/.pythonlibs/lib/python3.11/site-packages/sqlalchemy/engine/base.py\", line 2355, in _handle_dbapi_exception\n    raise sqlalchemy_exception.with_traceback(exc_info[2]) from e\n  File \"/home/runner/workspace/.pythonlibs/lib/python3.11/site-packages/sqlalchemy/engine/base.py\", line 1967, in _exec_single_context\n    self.dialect.do_execute(\n  File \"/home/runner/workspace/.pythonlibs/lib/python3.11/site-packages/sqlalchemy/engine/default.py\", line 941, in do_execute\n    cursor.execute(statement, parameters)\nsqlalchemy.exc.IntegrityError: (psycopg2.errors.ForeignKeyViolation) insert or update on table \"projects\" violates foreign key constraint \"projects_project_manager_fkey\"\nDETAIL:  Key (project_manager)=(-) is not present in table \"project_managers\".\n\n[SQL: UPDATE projects SET project_manager=%(project_manager)s, updated_at=now() WHERE projects.id = %(projects_id)s]\n[parameters: {'project_manager': '-', 'projects_id': 5}]\n(Background on this error at: https://sqlalche.me/e/20/gkpj)\n", "request_method": "PUT", "request_url": "http://6ed7ce35-85b3-498b-9e9b-4d63631ed8e3-00-2owzgyvztotfg.worf.replit.dev/projects/Aspers_PA", "request_headers": {"host": "6ed7ce35-85b3-498b-9e9b-4d63631ed8e3-00-2owzgyvztotfg.worf.replit.dev", "user-agent": "Mozilla/5.0 (Windows NT 10.0; Win64; x64) AppleWebKit/537.36 (KHTML, like Gecko) Chrome/132.0.0.0 Safari/537.36 Edg/132.0.0.0", "content-length": "249", "accept": "application/json, text/plain, */*", "accept-encoding": "gzip, deflate, br, zstd", "accept-language": "en-US,en;q=0.9", "content-type": "application/json", "origin": "https://kzmp76owp04myy2i31bn.lite.vusercontent.net", "referer": "https://kzmp76owp04myy2i31bn.lite.vusercontent.net/", "sec-ch-ua": "\"Not A(Brand\";v=\"8\", \"Chromium\";v=\"132\", \"Microsoft Edge\";v=\"132\"", "sec-ch-ua-mobile": "?0", "sec-ch-ua-platform": "\"Windows\"", "sec-fetch-dest": "empty", "sec-fetch-mode": "cors", "sec-fetch-site": "cross-site", "x-forwarded-for": "67.11.111.13, 165.225.36.171, 10.83.3.152", "x-forwarded-proto": "https", "x-replit-user-bio": "", "x-replit-user-id": "", "x-replit-user-name": "", "x-replit-user-profile-image": "", "x-replit-user-roles": "", "x-replit-user-teams": "", "x-replit-user-url": ""}, "client_host": "172.31.128.43", "query_params": {}, "path_params": {"project_id": "Aspers_PA"}, "path": "/projects/Aspers_PA", "origin": "https://kzmp76owp04myy2i31bn.lite.vusercontent.net", "cors_method": null, "cors_headers": null}}
{"timestamp": "2025-02-12T03:25:27.008786", "level": "DEBUG", "correlation_id": "7d84ecfd-7f1f-4793-9026-6348c3ba9986", "logger": "TimesheetTracker", "message": {"message": "Adding CORS headers to response", "timestamp": "2025-02-12T03:25:27.007904", "context": {"correlation_id": "7d84ecfd-7f1f-4793-9026-6348c3ba9986", "method": "PUT", "path": "/projects/Aspers_PA", "status_code": 500}}, "context": {}}
INFO:     172.31.128.43:50026 - "PUT /projects/Aspers_PA HTTP/1.1" 500 Internal Server Error